Workbook

Sheet Sheet1
A1: KEY | B1: KEY标签 | C1: 店铺ID | D1: 店铺名称
A2: 周奇 | B2: =VLOOKUP(A2,[1]主体维度!$A$1:$C$3000,3,0) -> S | C2: 634418210923138 | D2: Qian Gugu
A3: 周奇 | B3: =VLOOKUP(A3,[1]主体维度!$A$1:$C$3000,3,0) -> S | C3: 634418212414811 | D3: Ling Daozhe
A4: 周奇 | B4: =VLOOKUP(A4,[1]主体维度!$A$1:$C$3000,3,0) -> S | C4: 634418222692282 | D4: Yi Chen Fushi
A5: 周奇 | B5: =VLOOKUP(A5,[1]主体维度!$A$1:$C$3000,3,0) -> S | C5: 634418222746812 | D5: Yi Xuan FuShi
A6: 周奇 | B6: =VLOOKUP(A6,[1]主体维度!$A$1:$C$3000,3,0) -> S | C6: 634418213755266 | D6: Hui Guniang
A7: 周奇 | B7: =VLOOKUP(A7,[1]主体维度!$A$1:$C$3000,3,0) -> S | C7: 634418215719586 | D7: Putaoshu
A8: 周奇 | B8: =VLOOKUP(A8,[1]主体维度!$A$1:$C$3000,3,0) -> S | C8: 634418216266449 | D8: Da Xiaojie
A9: 周奇 | B9: =VLOOKUP(A9,[1]主体维度!$A$1:$C$3000,3,0) -> S | C9: 634418216474598 | D9: Qian Daizi
A10: 周奇 | B10: =VLOOKUP(A10,[1]主体维度!$A$1:$C$3000,3,0) -> S | C10: 634418216716288 | D10: Meng bali
A11: 周奇 | B11: =VLOOKUP(A11,[1]主体维度!$A$1:$C$3000,3,0) -> S | C11: 634418211972264 | D11: Xiao Guli
A12: Dress Brightly | B12: =VLOOKUP(A12,[1]主体维度!$A$1:$C$3000,3,0) -> S | C12: 634418210927341 | D12: Dress Brightly
A13: Dress Brightly | B13: =VLOOKUP(A13,[1]主体维度!$A$1:$C$3000,3,0) -> S | C13: 634418211551563 | D13: Enchanting Elegance Boutique
... A547: LLX-林总 | B547: =VLOOKUP(A547,[1]主体维度!$A$1:$C$3000,3,0) -> C | C547: 634418221766258 | D547: linmiaomiao
A548: LLX-林总 | B548: =VLOOKUP(A548,[1]主体维度!$A$1:$C$3000,3,0) -> C | C548: 634418221990004
A549: LLX-林总 | B549: =VLOOKUP(A549,[1]主体维度!$A$1:$C$3000,3,0) -> C | C549: 634418222023507 | D549: KLclothingstudio
A550: LLX-彭总 | B550: =VLOOKUP(A550,[1]主体维度!$A$1:$C$3000,3,0) -> C | C550: 634418210889113 | D550: HUA LI FASHION
A551: LLX-彭总 | B551: =VLOOKUP(A551,[1]主体维度!$A$1:$C$3000,3,0) -> C | C551: 634418225047545 | D551: YLQWH
A552: LLX-彭总 | B552: =VLOOKUP(A552,[1]主体维度!$A$1:$C$3000,3,0) -> C | C552: 634418227166118 | D552: YOULFUSHI
A553: LLX-彭总 | B553: =VLOOKUP(A553,[1]主体维度!$A$1:$C$3000,3,0) -> C | C553: 634418227401547 | D553: DYFCSWS
A554: LLX-彭总 | B554: =VLOOKUP(A554,[1]主体维度!$A$1:$C$3000,3,0) -> C | C554: 634418227491771 | D554: XFDress
A555: LLX-彭总 | B555: =VLOOKUP(A555,[1]主体维度!$A$1:$C$3000,3,0) -> C | C555: 634418227527932 | D555: PFXDM
A556: 芮羽服装厂 | B556: =VLOOKUP(A556,[1]主体维度!$A$1:$C$3000,3,0) -> B | C556: 634418221044566 | D556: Shencui
A557: 王鹏 | B557: =VLOOKUP(A557,[1]主体维度!$A$1:$C$3000,3,0) -> B | C557: 634418225975166 | D557: wenwanfuren
A558: 王鹏 | B558: =VLOOKUP(A558,[1]主体维度!$A$1:$C$3000,3,0) -> B | C558: 634418226888043 | D558: wangpengyiyi
A559: 王鹏 | B559: =VLOOKUP(A559,[1]主体维度!$A$1:$C$3000,3,0) -> B | C559: 634418226892212 | D559: The Style Chapter
A560: 吴总 Nova Veil | B560: =VLOOKUP(A560,[1]主体维度!$A$1:$C$3000,3,0) -> C | C560: 634418224135774 | D560: Nova Veil
... A619: 周得新 Shen Huxi | B619: =VLOOKUP(A619,[1]主体维度!$A$1:$C$3000,3,0) -> C | C619: 634418224339297 | D619: coconut CAT
A620: 周得新 Shen Huxi | B620: =VLOOKUP(A620,[1]主体维度!$A$1:$C$3000,3,0) -> C | C620: 634418222820499
A621: 周得新 Shen Huxi | B621: =VLOOKUP(A621,[1]主体维度!$A$1:$C$3000,3,0) -> C | C621: 634418224736209 | D621: Lollypop
A622: 周得新 Shen Huxi | B622: =VLOOKUP(A622,[1]主体维度!$A$1:$C$3000,3,0) -> C | C622: 634418224309428 | D622: SPARKLE BRIGHTLY
A623: The desire | B623: =VLOOKUP(A623,[1]主体维度!$A$1:$C$3000,3,0) -> B | C623: 634418224822060 | D623: The desire to shop
A624: Xixiha | B624: =VLOOKUP(A624,[1]主体维度!$A$1:$C$3000,3,0) -> B | C624: 634418218934393 | D624: Xixiha womens
A625: Xixiha | B625: =VLOOKUP(A625,[1]主体维度!$A$1:$C$3000,3,0) -> B | C625: 634418220417275 | D625: TIANJINXI
A626: Aiyang-张丽敏-珺红主体-林宏治负责 | B626: =VLOOKUP(A626,[1]主体维度!$A$1:$C$3000,3,0) -> C | C626: 634418217144788 | D626: Alamee
A627: Aiyang-张丽敏-珺红主体-林宏治负责 | B627: =VLOOKUP(A627,[1]主体维度!$A$1:$C$3000,3,0) -> C | C627: 634418217273712 | D627: Alauu
A628: Aiyang-张丽敏-珺红主体-林宏治负责 | B628: =VLOOKUP(A628,[1]主体维度!$A$1:$C$3000,3,0) -> C | C628: 634418218239165 | D628: CHINGE
A629: Aiyang-张丽敏-珺红主体-林宏治负责 | B629: =VLOOKUP(A629,[1]主体维度!$A$1:$C$3000,3,0) -> C | C629: 634418219317455 | D629: LIVII
A630: Aiyang-张丽敏-珺红主体-林宏治负责 | B630: =VLOOKUP(A630,[1]主体维度!$A$1:$C$3000,3,0) -> C | C630: 634418221516981 | D630: Alashaa
A631: Aiyang-张丽敏-珺红主体-林宏治负责 | B631: =VLOOKUP(A631,[1]主体维度!$A$1:$C$3000,3,0) -> C | C631: 634418221512084 | D631: Ala Vogue
...
